<?xml version='1.0'?>

<robot name="my_robot" xmlns:xacro="http://www.ros.org/wiki/xacro">
		
	<xacro:macro name="wheel_with_joint" params="parent_name left radius heigth jointX jointY jointZ">

		<xacro:property name="name_side" value="right"/>
		<xacro:property name="reflect_side" value="-1"/>
		<!-- evaluation -->		
		<xacro:if value="${left}">
			<xacro:property name="name_side" value="left"/>
			<xacro:property name="reflect_side" value="1"/>			
		</xacro:if>

		<xacro:wheel name="${name_side}_wheel" radius="${radius}" heigth="${heigth}">		
		</xacro:wheel>

		<joint type="continuous" name="${name_side}_wheel_hinge">
			<origin xyz="${jointX} ${reflect_side*jointY} ${jointZ}" rpy="0 0 0"/>
			<child link="${name_side}_wheel"/>
			<parent link="${parent_name}"/>
			<axis xyz="0 1 0" rpy="0 0 0"/>
			<limit effort="10000" velocity="1000"/>
			<joint_properties damping="1.0" friction="1.0"/>
		</joint>

	</xacro:macro>

</robot>
